Traceback (most recent call last):
  File "./main.py", line 4, in <module>
    from write_results import write_chains, plot_chains, write_mcmc_results, write_science_results
  File "/home/epfl/gorgoni/PhD/RSD/GS-model/write_results.py", line 3, in <module>
    from mcmc import lnlike
  File "/home/epfl/gorgoni/PhD/RSD/GS-model/mcmc.py", line 5, in <module>
    from GS_multi import xi_l, xi_02, xi_024
  File "/home/epfl/gorgoni/PhD/RSD/GS-model/GS_multi.py", line 1, in <module>
    import GS_sig_pi as gs
  File "/home/epfl/gorgoni/PhD/RSD/GS-model/GS_sig_pi.py", line 15, in <module>
    r = np.loadtxt(xi_file, unpack=True)[0]
  File "/astro/soft/common/gcc/5.4.0/python/2.7.15/lib/python2.7/site-packages/numpy/lib/npyio.py", line 926, in loadtxt
    fh = np.lib._datasource.open(fname, 'rt', encoding=encoding)
  File "/astro/soft/common/gcc/5.4.0/python/2.7.15/lib/python2.7/site-packages/numpy/lib/_datasource.py", line 260, in open
    return ds.open(path, mode, encoding=encoding, newline=newline)
  File "/astro/soft/common/gcc/5.4.0/python/2.7.15/lib/python2.7/site-packages/numpy/lib/_datasource.py", line 616, in open
    raise IOError("%s not found." % path)
IOError: ~/PhD/RSD/CLPT_GSRSD/data/xi_085.txt not found.
